==72582== Memcheck, a memory error detector
==72582== Copyright (C) 2002-2017, and GNU GPL'd, by Julian Seward et al.
==72582== Using Valgrind-3.18.1 and LibVEX; rerun with -h for copyright info
==72582== Command: /usr/bin/python3 /home/gabor/webserv/cgi-bin/python3/kill.py
==72582== Parent PID: 72540
==72582== 
==72582== 
==72582== Process terminating with default action of signal 15 (SIGTERM)
==72582==    at 0x22FF84: PyType_GenericAlloc (in /usr/bin/python3.10)
==72582==    by 0x22B0BA: PyType_Ready (in /usr/bin/python3.10)
==72582==    by 0x339830: ??? (in /usr/bin/python3.10)
==72582==    by 0x221ED2: ??? (in /usr/bin/python3.10)
==72582==    by 0x333867: ??? (in /usr/bin/python3.10)
==72582==    by 0x333586: Py_InitializeFromConfig (in /usr/bin/python3.10)
==72582==    by 0x330EEF: ??? (in /usr/bin/python3.10)
==72582==    by 0x330E24: ??? (in /usr/bin/python3.10)
==72582==    by 0x330DFC: Py_BytesMain (in /usr/bin/python3.10)
==72582==    by 0x49CBD8F: (below main) (libc_start_call_main.h:58)
==72582== 
==72582== FILE DESCRIPTORS: 5 open (3 std) at exit.
==72582== Open file descriptor 4: /home/gabor/webserv/cgi-bin/python3/valtmp
==72582==    <inherited from parent>
==72582== 
==72582== Open file descriptor 3: /home/gabor/webserv/valtmp
==72582==    <inherited from parent>
==72582== 
==72582== 
==72582== HEAP SUMMARY:
==72582==     in use at exit: 527,999 bytes in 65 blocks
==72582==   total heap usage: 122 allocs, 57 frees, 544,354 bytes allocated
==72582== 
==72582== 7 bytes in 1 blocks are still reachable in loss record 1 of 59
==72582==    at 0x4848899: malloc (in /usr/libexec/valgrind/vgpreload_memcheck-amd64-linux.so)
==72582==    by 0x4A4A5CE: strndup (strndup.c:43)
==72582==    by 0x49D9814: _nl_find_locale (findlocale.c:310)
==72582==    by 0x49D8A90: setlocale (setlocale.c:414)
==72582==    by 0x49D8A90: setlocale (setlocale.c:217)
==72582==    by 0x332F50: _Py_CoerceLegacyLocale (in /usr/bin/python3.10)
==72582==    by 0x331A8E: _Py_PreInitializeFromPyArgv (in /usr/bin/python3.10)
==72582==    by 0x330EAE: ??? (in /usr/bin/python3.10)
==72582==    by 0x330E24: ??? (in /usr/bin/python3.10)
==72582==    by 0x330DFC: Py_BytesMain (in /usr/bin/python3.10)
==72582==    by 0x49CBD8F: (below main) (libc_start_call_main.h:58)
==72582== 
==72582== 8 bytes in 1 blocks are still reachable in loss record 2 of 59
==72582==    at 0x4848899: malloc (in /usr/libexec/valgrind/vgpreload_memcheck-amd64-linux.so)
==72582==    by 0x4A4A58E: strdup (strdup.c:42)
==72582==    by 0x49D8ACA: setlocale (setlocale.c:431)
==72582==    by 0x49D8ACA: setlocale (setlocale.c:217)
==72582==    by 0x331E40: _Py_SetLocaleFromEnv (in /usr/bin/python3.10)
==72582==    by 0x331A0E: _Py_PreInitializeFromPyArgv (in /usr/bin/python3.10)
==72582==    by 0x330EAE: ??? (in /usr/bin/python3.10)
==72582==    by 0x330E24: ??? (in /usr/bin/python3.10)
==72582==    by 0x330DFC: Py_BytesMain (in /usr/bin/python3.10)
==72582==    by 0x49CBD8F: (below main) (libc_start_call_main.h:58)
==72582== 
==72582== 8 bytes in 1 blocks are still reachable in loss record 3 of 59
==72582==    at 0x4848899: malloc (in /usr/libexec/valgrind/vgpreload_memcheck-amd64-linux.so)
==72582==    by 0x33430C: _PyWideStringList_Copy (in /usr/bin/python3.10)
==72582==    by 0x3349A2: ??? (in /usr/bin/python3.10)
==72582==    by 0x3336ED: ??? (in /usr/bin/python3.10)
==72582==    by 0x333586: Py_InitializeFromConfig (in /usr/bin/python3.10)
==72582==    by 0x330EEF: ??? (in /usr/bin/python3.10)
==72582==    by 0x330E24: ??? (in /usr/bin/python3.10)
==72582==    by 0x330DFC: Py_BytesMain (in /usr/bin/python3.10)
==72582==    by 0x49CBD8F: (below main) (libc_start_call_main.h:58)
==72582== 
==72582== 8 bytes in 1 blocks are still reachable in loss record 4 of 59
==72582==    at 0x4848899: malloc (in /usr/libexec/valgrind/vgpreload_memcheck-amd64-linux.so)
==72582==    by 0x33430C: _PyWideStringList_Copy (in /usr/bin/python3.10)
==72582==    by 0x333A5B: ??? (in /usr/bin/python3.10)
==72582==    by 0x3337F3: ??? (in /usr/bin/python3.10)
==72582==    by 0x333586: Py_InitializeFromConfig (in /usr/bin/python3.10)
==72582==    by 0x330EEF: ??? (in /usr/bin/python3.10)
==72582==    by 0x330E24: ??? (in /usr/bin/python3.10)
==72582==    by 0x330DFC: Py_BytesMain (in /usr/bin/python3.10)
==72582==    by 0x49CBD8F: (below main) (libc_start_call_main.h:58)
==72582== 
==72582== 16 bytes in 1 blocks are still reachable in loss record 5 of 59
==72582==    at 0x4848899: malloc (in /usr/libexec/valgrind/vgpreload_memcheck-amd64-linux.so)
==72582==    by 0x331EC9: _PyArgv_AsWstrList (in /usr/bin/python3.10)
==72582==    by 0x3334C5: ??? (in /usr/bin/python3.10)
==72582==    by 0x33347E: PyConfig_SetBytesArgv (in /usr/bin/python3.10)
==72582==    by 0x330EDD: ??? (in /usr/bin/python3.10)
==72582==    by 0x330E24: ??? (in /usr/bin/python3.10)
==72582==    by 0x330DFC: Py_BytesMain (in /usr/bin/python3.10)
==72582==    by 0x49CBD8F: (below main) (libc_start_call_main.h:58)
==72582== 
==72582== 16 bytes in 1 blocks are still reachable in loss record 6 of 59
==72582==    at 0x4848899: malloc (in /usr/libexec/valgrind/vgpreload_memcheck-amd64-linux.so)
==72582==    by 0x33430C: _PyWideStringList_Copy (in /usr/bin/python3.10)
==72582==    by 0x3345B0: ??? (in /usr/bin/python3.10)
==72582==    by 0x3336ED: ??? (in /usr/bin/python3.10)
==72582==    by 0x333586: Py_InitializeFromConfig (in /usr/bin/python3.10)
==72582==    by 0x330EEF: ??? (in /usr/bin/python3.10)
==72582==    by 0x330E24: ??? (in /usr/bin/python3.10)
==72582==    by 0x330DFC: Py_BytesMain (in /usr/bin/python3.10)
==72582==    by 0x49CBD8F: (below main) (libc_start_call_main.h:58)
==72582== 
==72582== 16 bytes in 1 blocks are still reachable in loss record 7 of 59
==72582==    at 0x4848899: malloc (in /usr/libexec/valgrind/vgpreload_memcheck-amd64-linux.so)
==72582==    by 0x332DB1: ??? (in /usr/bin/python3.10)
==72582==    by 0x331F64: Py_DecodeLocale (in /usr/bin/python3.10)
==72582==    by 0x3369C2: ??? (in /usr/bin/python3.10)
==72582==    by 0x3350B7: ??? (in /usr/bin/python3.10)
==72582==    by 0x3336ED: ??? (in /usr/bin/python3.10)
==72582==    by 0x333586: Py_InitializeFromConfig (in /usr/bin/python3.10)
==72582==    by 0x330EEF: ??? (in /usr/bin/python3.10)
==72582==    by 0x330E24: ??? (in /usr/bin/python3.10)
==72582==    by 0x330DFC: Py_BytesMain (in /usr/bin/python3.10)
==72582==    by 0x49CBD8F: (below main) (libc_start_call_main.h:58)
==72582== 
==72582== 16 bytes in 1 blocks are still reachable in loss record 8 of 59
==72582==    at 0x4848899: malloc (in /usr/libexec/valgrind/vgpreload_memcheck-amd64-linux.so)
==72582==    by 0x33430C: _PyWideStringList_Copy (in /usr/bin/python3.10)
==72582==    by 0x337E90: ??? (in /usr/bin/python3.10)
==72582==    by 0x333737: ??? (in /usr/bin/python3.10)
==72582==    by 0x333586: Py_InitializeFromConfig (in /usr/bin/python3.10)
==72582==    by 0x330EEF: ??? (in /usr/bin/python3.10)
==72582==    by 0x330E24: ??? (in /usr/bin/python3.10)
==72582==    by 0x330DFC: Py_BytesMain (in /usr/bin/python3.10)
==72582==    by 0x49CBD8F: (below main) (libc_start_call_main.h:58)
==72582== 
==72582== 16 bytes in 1 blocks are still reachable in loss record 9 of 59
==72582==    at 0x4848899: malloc (in /usr/libexec/valgrind/vgpreload_memcheck-amd64-linux.so)
==72582==    by 0x332CBA: _PyMem_RawWcsdup (in /usr/bin/python3.10)
==72582==    by 0x334158: PyConfig_SetString (in /usr/bin/python3.10)
==72582==    by 0x333BA7: ??? (in /usr/bin/python3.10)
==72582==    by 0x3337F3: ??? (in /usr/bin/python3.10)
==72582==    by 0x333586: Py_InitializeFromConfig (in /usr/bin/python3.10)
==72582==    by 0x330EEF: ??? (in /usr/bin/python3.10)
==72582==    by 0x330E24: ??? (in /usr/bin/python3.10)
==72582==    by 0x330DFC: Py_BytesMain (in /usr/bin/python3.10)
==72582==    by 0x49CBD8F: (below main) (libc_start_call_main.h:58)
==72582== 
==72582== 16 bytes in 1 blocks are still reachable in loss record 10 of 59
==72582==    at 0x4848899: malloc (in /usr/libexec/valgrind/vgpreload_memcheck-amd64-linux.so)
==72582==    by 0x33430C: _PyWideStringList_Copy (in /usr/bin/python3.10)
==72582==    by 0x333D2B: ??? (in /usr/bin/python3.10)
==72582==    by 0x3337F3: ??? (in /usr/bin/python3.10)
==72582==    by 0x333586: Py_InitializeFromConfig (in /usr/bin/python3.10)
==72582==    by 0x330EEF: ??? (in /usr/bin/python3.10)
==72582==    by 0x330E24: ??? (in /usr/bin/python3.10)
==72582==    by 0x330DFC: Py_BytesMain (in /usr/bin/python3.10)
==72582==    by 0x49CBD8F: (below main) (libc_start_call_main.h:58)
==72582== 
==72582== 17 bytes in 1 blocks are still reachable in loss record 11 of 59
==72582==    at 0x4848899: malloc (in /usr/libexec/valgrind/vgpreload_memcheck-amd64-linux.so)
==72582==    by 0x49E703F: __add_to_environ (setenv.c:217)
==72582==    by 0x48543FF: setenv (in /usr/libexec/valgrind/vgpreload_memcheck-amd64-linux.so)
==72582==    by 0x332FAB: _Py_CoerceLegacyLocale (in /usr/bin/python3.10)
==72582==    by 0x331A8E: _Py_PreInitializeFromPyArgv (in /usr/bin/python3.10)
==72582==    by 0x330EAE: ??? (in /usr/bin/python3.10)
==72582==    by 0x330E24: ??? (in /usr/bin/python3.10)
==72582==    by 0x330DFC: Py_BytesMain (in /usr/bin/python3.10)
==72582==    by 0x49CBD8F: (below main) (libc_start_call_main.h:58)
==72582== 
==72582== 24 bytes in 1 blocks are still reachable in loss record 12 of 59
==72582==    at 0x4848899: malloc (in /usr/libexec/valgrind/vgpreload_memcheck-amd64-linux.so)
==72582==    by 0x4AC1F34: tsearch (tsearch.c:337)
==72582==    by 0x49E706A: __add_to_environ (setenv.c:233)
==72582==    by 0x48543FF: setenv (in /usr/libexec/valgrind/vgpreload_memcheck-amd64-linux.so)
==72582==    by 0x332FAB: _Py_CoerceLegacyLocale (in /usr/bin/python3.10)
==72582==    by 0x331A8E: _Py_PreInitializeFromPyArgv (in /usr/bin/python3.10)
==72582==    by 0x330EAE: ??? (in /usr/bin/python3.10)
==72582==    by 0x330E24: ??? (in /usr/bin/python3.10)
==72582==    by 0x330DFC: Py_BytesMain (in /usr/bin/python3.10)
==72582==    by 0x49CBD8F: (below main) (libc_start_call_main.h:58)
==72582== 
==72582== 24 bytes in 1 blocks are still reachable in loss record 13 of 59
==72582==    at 0x4848899: malloc (in /usr/libexec/valgrind/vgpreload_memcheck-amd64-linux.so)
==72582==    by 0x332CBA: _PyMem_RawWcsdup (in /usr/bin/python3.10)
==72582==    by 0x334158: PyConfig_SetString (in /usr/bin/python3.10)
==72582==    by 0x33556E: ??? (in /usr/bin/python3.10)
==72582==    by 0x3336ED: ??? (in /usr/bin/python3.10)
==72582==    by 0x333586: Py_InitializeFromConfig (in /usr/bin/python3.10)
==72582==    by 0x330EEF: ??? (in /usr/bin/python3.10)
==72582==    by 0x330E24: ??? (in /usr/bin/python3.10)
==72582==    by 0x330DFC: Py_BytesMain (in /usr/bin/python3.10)
==72582==    by 0x49CBD8F: (below main) (libc_start_call_main.h:58)
==72582== 
==72582== 24 bytes in 1 blocks are still reachable in loss record 14 of 59
==72582==    at 0x4848899: malloc (in /usr/libexec/valgrind/vgpreload_memcheck-amd64-linux.so)
==72582==    by 0x332CBA: _PyMem_RawWcsdup (in /usr/bin/python3.10)
==72582==    by 0x334158: PyConfig_SetString (in /usr/bin/python3.10)
==72582==    by 0x337BC5: ??? (in /usr/bin/python3.10)
==72582==    by 0x335245: ??? (in /usr/bin/python3.10)
==72582==    by 0x3336ED: ??? (in /usr/bin/python3.10)
==72582==    by 0x333586: Py_InitializeFromConfig (in /usr/bin/python3.10)
==72582==    by 0x330EEF: ??? (in /usr/bin/python3.10)
==72582==    by 0x330E24: ??? (in /usr/bin/python3.10)
==72582==    by 0x330DFC: Py_BytesMain (in /usr/bin/python3.10)
==72582==    by 0x49CBD8F: (below main) (libc_start_call_main.h:58)
==72582== 
==72582== 24 bytes in 1 blocks are still reachable in loss record 15 of 59
==72582==    at 0x4848899: malloc (in /usr/libexec/valgrind/vgpreload_memcheck-amd64-linux.so)
==72582==    by 0x332CBA: _PyMem_RawWcsdup (in /usr/bin/python3.10)
==72582==    by 0x334158: PyConfig_SetString (in /usr/bin/python3.10)
==72582==    by 0x333BFF: ??? (in /usr/bin/python3.10)
==72582==    by 0x3337F3: ??? (in /usr/bin/python3.10)
==72582==    by 0x333586: Py_InitializeFromConfig (in /usr/bin/python3.10)
==72582==    by 0x330EEF: ??? (in /usr/bin/python3.10)
==72582==    by 0x330E24: ??? (in /usr/bin/python3.10)
==72582==    by 0x330DFC: Py_BytesMain (in /usr/bin/python3.10)
==72582==    by 0x49CBD8F: (below main) (libc_start_call_main.h:58)
==72582== 
==72582== 24 bytes in 1 blocks are still reachable in loss record 16 of 59
==72582==    at 0x4848899: malloc (in /usr/libexec/valgrind/vgpreload_memcheck-amd64-linux.so)
==72582==    by 0x332CBA: _PyMem_RawWcsdup (in /usr/bin/python3.10)
==72582==    by 0x334158: PyConfig_SetString (in /usr/bin/python3.10)
==72582==    by 0x333C3F: ??? (in /usr/bin/python3.10)
==72582==    by 0x3337F3: ??? (in /usr/bin/python3.10)
==72582==    by 0x333586: Py_InitializeFromConfig (in /usr/bin/python3.10)
==72582==    by 0x330EEF: ??? (in /usr/bin/python3.10)
==72582==    by 0x330E24: ??? (in /usr/bin/python3.10)
==72582==    by 0x330DFC: Py_BytesMain (in /usr/bin/python3.10)
==72582==    by 0x49CBD8F: (below main) (libc_start_call_main.h:58)
==72582== 
==72582== 27 bytes in 1 blocks are still reachable in loss record 17 of 59
==72582==    at 0x4848899: malloc (in /usr/libexec/valgrind/vgpreload_memcheck-amd64-linux.so)
==72582==    by 0x49DFE4C: _nl_make_l10nflist (l10nflist.c:166)
==72582==    by 0x49E0211: _nl_make_l10nflist (l10nflist.c:285)
==72582==    by 0x49E0211: _nl_make_l10nflist (l10nflist.c:285)
==72582==    by 0x49D9747: _nl_find_locale (findlocale.c:214)
==72582==    by 0x49D8A90: setlocale (setlocale.c:414)
==72582==    by 0x49D8A90: setlocale (setlocale.c:217)
==72582==    by 0x332F50: _Py_CoerceLegacyLocale (in /usr/bin/python3.10)
==72582==    by 0x331A8E: _Py_PreInitializeFromPyArgv (in /usr/bin/python3.10)
==72582==    by 0x330EAE: ??? (in /usr/bin/python3.10)
==72582==    by 0x330E24: ??? (in /usr/bin/python3.10)
==72582==    by 0x330DFC: Py_BytesMain (in /usr/bin/python3.10)
==72582==    by 0x49CBD8F: (below main) (libc_start_call_main.h:58)
==72582== 
==72582== 32 bytes in 1 blocks are still reachable in loss record 18 of 59
==72582==    at 0x4848899: malloc (in /usr/libexec/valgrind/vgpreload_memcheck-amd64-linux.so)
==72582==    by 0x2205F3: PyThread_allocate_lock (in /usr/bin/python3.10)
==72582==    by 0x33102F: _PyRuntimeState_Init (in /usr/bin/python3.10)
==72582==    by 0x330F76: _PyRuntime_Initialize (in /usr/bin/python3.10)
==72582==    by 0x330E8D: ??? (in /usr/bin/python3.10)
==72582==    by 0x330E24: ??? (in /usr/bin/python3.10)
==72582==    by 0x330DFC: Py_BytesMain (in /usr/bin/python3.10)
==72582==    by 0x49CBD8F: (below main) (libc_start_call_main.h:58)
==72582== 
==72582== 32 bytes in 1 blocks are still reachable in loss record 19 of 59
==72582==    at 0x4848899: malloc (in /usr/libexec/valgrind/vgpreload_memcheck-amd64-linux.so)
==72582==    by 0x2205F3: PyThread_allocate_lock (in /usr/bin/python3.10)
==72582==    by 0x331049: _PyRuntimeState_Init (in /usr/bin/python3.10)
==72582==    by 0x330F76: _PyRuntime_Initialize (in /usr/bin/python3.10)
==72582==    by 0x330E8D: ??? (in /usr/bin/python3.10)
==72582==    by 0x330E24: ??? (in /usr/bin/python3.10)
==72582==    by 0x330DFC: Py_BytesMain (in /usr/bin/python3.10)
==72582==    by 0x49CBD8F: (below main) (libc_start_call_main.h:58)
==72582== 
==72582== 32 bytes in 1 blocks are still reachable in loss record 20 of 59
==72582==    at 0x4848899: malloc (in /usr/libexec/valgrind/vgpreload_memcheck-amd64-linux.so)
==72582==    by 0x2205F3: PyThread_allocate_lock (in /usr/bin/python3.10)
==72582==    by 0x331064: _PyRuntimeState_Init (in /usr/bin/python3.10)
==72582==    by 0x330F76: _PyRuntime_Initialize (in /usr/bin/python3.10)
==72582==    by 0x330E8D: ??? (in /usr/bin/python3.10)
==72582==    by 0x330E24: ??? (in /usr/bin/python3.10)
==72582==    by 0x330DFC: Py_BytesMain (in /usr/bin/python3.10)
==72582==    by 0x49CBD8F: (below main) (libc_start_call_main.h:58)
==72582== 
==72582== 32 bytes in 1 blocks are still reachable in loss record 21 of 59
==72582==    at 0x4848899: malloc (in /usr/libexec/valgrind/vgpreload_memcheck-amd64-linux.so)
==72582==    by 0x332CBA: _PyMem_RawWcsdup (in /usr/bin/python3.10)
==72582==    by 0x334158: PyConfig_SetString (in /usr/bin/python3.10)
==72582==    by 0x33531D: ??? (in /usr/bin/python3.10)
==72582==    by 0x3336ED: ??? (in /usr/bin/python3.10)
==72582==    by 0x333586: Py_InitializeFromConfig (in /usr/bin/python3.10)
==72582==    by 0x330EEF: ??? (in /usr/bin/python3.10)
==72582==    by 0x330E24: ??? (in /usr/bin/python3.10)
==72582==    by 0x330DFC: Py_BytesMain (in /usr/bin/python3.10)
==72582==    by 0x49CBD8F: (below main) (libc_start_call_main.h:58)
==72582== 
==72582== 32 bytes in 1 blocks are still reachable in loss record 22 of 59
==72582==    at 0x4848899: malloc (in /usr/libexec/valgrind/vgpreload_memcheck-amd64-linux.so)
==72582==    by 0x2205F3: PyThread_allocate_lock (in /usr/bin/python3.10)
==72582==    by 0x338119: PyInterpreterState_New (in /usr/bin/python3.10)
==72582==    by 0x3337D3: ??? (in /usr/bin/python3.10)
==72582==    by 0x333586: Py_InitializeFromConfig (in /usr/bin/python3.10)
==72582==    by 0x330EEF: ??? (in /usr/bin/python3.10)
==72582==    by 0x330E24: ??? (in /usr/bin/python3.10)
==72582==    by 0x330DFC: Py_BytesMain (in /usr/bin/python3.10)
==72582==    by 0x49CBD8F: (below main) (libc_start_call_main.h:58)
==72582== 
==72582== 32 bytes in 1 blocks are still reachable in loss record 23 of 59
==72582==    at 0x4848899: malloc (in /usr/libexec/valgrind/vgpreload_memcheck-amd64-linux.so)
==72582==    by 0x332CBA: _PyMem_RawWcsdup (in /usr/bin/python3.10)
==72582==    by 0x334158: PyConfig_SetString (in /usr/bin/python3.10)
==72582==    by 0x333CFA: ??? (in /usr/bin/python3.10)
==72582==    by 0x3337F3: ??? (in /usr/bin/python3.10)
==72582==    by 0x333586: Py_InitializeFromConfig (in /usr/bin/python3.10)
==72582==    by 0x330EEF: ??? (in /usr/bin/python3.10)
==72582==    by 0x330E24: ??? (in /usr/bin/python3.10)
==72582==    by 0x330DFC: Py_BytesMain (in /usr/bin/python3.10)
==72582==    by 0x49CBD8F: (below main) (libc_start_call_main.h:58)
==72582== 
==72582== 38 bytes in 1 blocks are still reachable in loss record 24 of 59
==72582==    at 0x4848899: malloc (in /usr/libexec/valgrind/vgpreload_memcheck-amd64-linux.so)
==72582==    by 0x49DFE4C: _nl_make_l10nflist (l10nflist.c:166)
==72582==    by 0x49D9747: _nl_find_locale (findlocale.c:214)
==72582==    by 0x49D8A90: setlocale (setlocale.c:414)
==72582==    by 0x49D8A90: setlocale (setlocale.c:217)
==72582==    by 0x332F50: _Py_CoerceLegacyLocale (in /usr/bin/python3.10)
==72582==    by 0x331A8E: _Py_PreInitializeFromPyArgv (in /usr/bin/python3.10)
==72582==    by 0x330EAE: ??? (in /usr/bin/python3.10)
==72582==    by 0x330E24: ??? (in /usr/bin/python3.10)
==72582==    by 0x330DFC: Py_BytesMain (in /usr/bin/python3.10)
==72582==    by 0x49CBD8F: (below main) (libc_start_call_main.h:58)
==72582== 
==72582== 56 bytes in 1 blocks are still reachable in loss record 25 of 59
==72582==    at 0x4848899: malloc (in /usr/libexec/valgrind/vgpreload_memcheck-amd64-linux.so)
==72582==    by 0x49DFFDC: _nl_make_l10nflist (l10nflist.c:242)
==72582==    by 0x49E0211: _nl_make_l10nflist (l10nflist.c:285)
==72582==    by 0x49E0211: _nl_make_l10nflist (l10nflist.c:285)
==72582==    by 0x49D9747: _nl_find_locale (findlocale.c:214)
==72582==    by 0x49D8A90: setlocale (setlocale.c:414)
==72582==    by 0x49D8A90: setlocale (setlocale.c:217)
==72582==    by 0x332F50: _Py_CoerceLegacyLocale (in /usr/bin/python3.10)
==72582==    by 0x331A8E: _Py_PreInitializeFromPyArgv (in /usr/bin/python3.10)
==72582==    by 0x330EAE: ??? (in /usr/bin/python3.10)
==72582==    by 0x330E24: ??? (in /usr/bin/python3.10)
==72582==    by 0x330DFC: Py_BytesMain (in /usr/bin/python3.10)
==72582==    by 0x49CBD8F: (below main) (libc_start_call_main.h:58)
==72582== 
==72582== 64 bytes in 1 blocks are still reachable in loss record 26 of 59
==72582==    at 0x4848899: malloc (in /usr/libexec/valgrind/vgpreload_memcheck-amd64-linux.so)
==72582==    by 0x332CBA: _PyMem_RawWcsdup (in /usr/bin/python3.10)
==72582==    by 0x334158: PyConfig_SetString (in /usr/bin/python3.10)
==72582==    by 0x3351C4: ??? (in /usr/bin/python3.10)
==72582==    by 0x3336ED: ??? (in /usr/bin/python3.10)
==72582==    by 0x333586: Py_InitializeFromConfig (in /usr/bin/python3.10)
==72582==    by 0x330EEF: ??? (in /usr/bin/python3.10)
==72582==    by 0x330E24: ??? (in /usr/bin/python3.10)
==72582==    by 0x330DFC: Py_BytesMain (in /usr/bin/python3.10)
==72582==    by 0x49CBD8F: (below main) (libc_start_call_main.h:58)
==72582== 
==72582== 64 bytes in 1 blocks are still reachable in loss record 27 of 59
==72582==    at 0x4848899: malloc (in /usr/libexec/valgrind/vgpreload_memcheck-amd64-linux.so)
==72582==    by 0x332CBA: _PyMem_RawWcsdup (in /usr/bin/python3.10)
==72582==    by 0x334158: PyConfig_SetString (in /usr/bin/python3.10)
==72582==    by 0x3352D9: ??? (in /usr/bin/python3.10)
==72582==    by 0x3336ED: ??? (in /usr/bin/python3.10)
==72582==    by 0x333586: Py_InitializeFromConfig (in /usr/bin/python3.10)
==72582==    by 0x330EEF: ??? (in /usr/bin/python3.10)
==72582==    by 0x330E24: ??? (in /usr/bin/python3.10)
==72582==    by 0x330DFC: Py_BytesMain (in /usr/bin/python3.10)
==72582==    by 0x49CBD8F: (below main) (libc_start_call_main.h:58)
==72582== 
==72582== 64 bytes in 1 blocks are still reachable in loss record 28 of 59
==72582==    at 0x4848899: malloc (in /usr/libexec/valgrind/vgpreload_memcheck-amd64-linux.so)
==72582==    by 0x332CBA: _PyMem_RawWcsdup (in /usr/bin/python3.10)
==72582==    by 0x334158: PyConfig_SetString (in /usr/bin/python3.10)
==72582==    by 0x333C1C: ??? (in /usr/bin/python3.10)
==72582==    by 0x3337F3: ??? (in /usr/bin/python3.10)
==72582==    by 0x333586: Py_InitializeFromConfig (in /usr/bin/python3.10)
==72582==    by 0x330EEF: ??? (in /usr/bin/python3.10)
==72582==    by 0x330E24: ??? (in /usr/bin/python3.10)
==72582==    by 0x330DFC: Py_BytesMain (in /usr/bin/python3.10)
==72582==    by 0x49CBD8F: (below main) (libc_start_call_main.h:58)
==72582== 
==72582== 64 bytes in 1 blocks are still reachable in loss record 29 of 59
==72582==    at 0x4848899: malloc (in /usr/libexec/valgrind/vgpreload_memcheck-amd64-linux.so)
==72582==    by 0x332CBA: _PyMem_RawWcsdup (in /usr/bin/python3.10)
==72582==    by 0x334158: PyConfig_SetString (in /usr/bin/python3.10)
==72582==    by 0x333C62: ??? (in /usr/bin/python3.10)
==72582==    by 0x3337F3: ??? (in /usr/bin/python3.10)
==72582==    by 0x333586: Py_InitializeFromConfig (in /usr/bin/python3.10)
==72582==    by 0x330EEF: ??? (in /usr/bin/python3.10)
==72582==    by 0x330E24: ??? (in /usr/bin/python3.10)
==72582==    by 0x330DFC: Py_BytesMain (in /usr/bin/python3.10)
==72582==    by 0x49CBD8F: (below main) (libc_start_call_main.h:58)
==72582== 
==72582== 65 bytes in 2 blocks are still reachable in loss record 30 of 59
==72582==    at 0x4848899: malloc (in /usr/libexec/valgrind/vgpreload_memcheck-amd64-linux.so)
==72582==    by 0x49DFE4C: _nl_make_l10nflist (l10nflist.c:166)
==72582==    by 0x49E0211: _nl_make_l10nflist (l10nflist.c:285)
==72582==    by 0x49D9747: _nl_find_locale (findlocale.c:214)
==72582==    by 0x49D8A90: setlocale (setlocale.c:414)
==72582==    by 0x49D8A90: setlocale (setlocale.c:217)
==72582==    by 0x332F50: _Py_CoerceLegacyLocale (in /usr/bin/python3.10)
==72582==    by 0x331A8E: _Py_PreInitializeFromPyArgv (in /usr/bin/python3.10)
==72582==    by 0x330EAE: ??? (in /usr/bin/python3.10)
==72582==    by 0x330E24: ??? (in /usr/bin/python3.10)
==72582==    by 0x330DFC: Py_BytesMain (in /usr/bin/python3.10)
==72582==    by 0x49CBD8F: (below main) (libc_start_call_main.h:58)
==72582== 
==72582== 68 bytes in 1 blocks are still reachable in loss record 31 of 59
==72582==    at 0x4848899: malloc (in /usr/libexec/valgrind/vgpreload_memcheck-amd64-linux.so)
==72582==    by 0x332CBA: _PyMem_RawWcsdup (in /usr/bin/python3.10)
==72582==    by 0x3347FA: ??? (in /usr/bin/python3.10)
==72582==    by 0x3336ED: ??? (in /usr/bin/python3.10)
==72582==    by 0x333586: Py_InitializeFromConfig (in /usr/bin/python3.10)
==72582==    by 0x330EEF: ??? (in /usr/bin/python3.10)
==72582==    by 0x330E24: ??? (in /usr/bin/python3.10)
==72582==    by 0x330DFC: Py_BytesMain (in /usr/bin/python3.10)
==72582==    by 0x49CBD8F: (below main) (libc_start_call_main.h:58)
==72582== 
==72582== 68 bytes in 1 blocks are still reachable in loss record 32 of 59
==72582==    at 0x4848899: malloc (in /usr/libexec/valgrind/vgpreload_memcheck-amd64-linux.so)
==72582==    by 0x332CBA: _PyMem_RawWcsdup (in /usr/bin/python3.10)
==72582==    by 0x334158: PyConfig_SetString (in /usr/bin/python3.10)
==72582==    by 0x333A3C: ??? (in /usr/bin/python3.10)
==72582==    by 0x3337F3: ??? (in /usr/bin/python3.10)
==72582==    by 0x333586: Py_InitializeFromConfig (in /usr/bin/python3.10)
==72582==    by 0x330EEF: ??? (in /usr/bin/python3.10)
==72582==    by 0x330E24: ??? (in /usr/bin/python3.10)
==72582==    by 0x330DFC: Py_BytesMain (in /usr/bin/python3.10)
==72582==    by 0x49CBD8F: (below main) (libc_start_call_main.h:58)
==72582== 
==72582== 104 bytes in 1 blocks are still reachable in loss record 33 of 59
==72582==    at 0x4848899: malloc (in /usr/libexec/valgrind/vgpreload_memcheck-amd64-linux.so)
==72582==    by 0x49DFFDC: _nl_make_l10nflist (l10nflist.c:242)
==72582==    by 0x49D9747: _nl_find_locale (findlocale.c:214)
==72582==    by 0x49D8A90: setlocale (setlocale.c:414)
==72582==    by 0x49D8A90: setlocale (setlocale.c:217)
==72582==    by 0x332F50: _Py_CoerceLegacyLocale (in /usr/bin/python3.10)
==72582==    by 0x331A8E: _Py_PreInitializeFromPyArgv (in /usr/bin/python3.10)
==72582==    by 0x330EAE: ??? (in /usr/bin/python3.10)
==72582==    by 0x330E24: ??? (in /usr/bin/python3.10)
==72582==    by 0x330DFC: Py_BytesMain (in /usr/bin/python3.10)
==72582==    by 0x49CBD8F: (below main) (libc_start_call_main.h:58)
==72582== 
==72582== 144 bytes in 2 blocks are still reachable in loss record 34 of 59
==72582==    at 0x4848899: malloc (in /usr/libexec/valgrind/vgpreload_memcheck-amd64-linux.so)
==72582==    by 0x49DFFDC: _nl_make_l10nflist (l10nflist.c:242)
==72582==    by 0x49E0211: _nl_make_l10nflist (l10nflist.c:285)
==72582==    by 0x49D9747: _nl_find_locale (findlocale.c:214)
==72582==    by 0x49D8A90: setlocale (setlocale.c:414)
==72582==    by 0x49D8A90: setlocale (setlocale.c:217)
==72582==    by 0x332F50: _Py_CoerceLegacyLocale (in /usr/bin/python3.10)
==72582==    by 0x331A8E: _Py_PreInitializeFromPyArgv (in /usr/bin/python3.10)
==72582==    by 0x330EAE: ??? (in /usr/bin/python3.10)
==72582==    by 0x330E24: ??? (in /usr/bin/python3.10)
==72582==    by 0x330DFC: Py_BytesMain (in /usr/bin/python3.10)
==72582==    by 0x49CBD8F: (below main) (libc_start_call_main.h:58)
==72582== 
==72582== 152 bytes in 1 blocks are still reachable in loss record 35 of 59
==72582==    at 0x48487A9: malloc (in /usr/libexec/valgrind/vgpreload_memcheck-amd64-linux.so)
==72582==    by 0x49E6E7B: __add_to_environ (setenv.c:156)
==72582==    by 0x48543FF: setenv (in /usr/libexec/valgrind/vgpreload_memcheck-amd64-linux.so)
==72582==    by 0x332FAB: _Py_CoerceLegacyLocale (in /usr/bin/python3.10)
==72582==    by 0x331A8E: _Py_PreInitializeFromPyArgv (in /usr/bin/python3.10)
==72582==    by 0x330EAE: ??? (in /usr/bin/python3.10)
==72582==    by 0x330E24: ??? (in /usr/bin/python3.10)
==72582==    by 0x330DFC: Py_BytesMain (in /usr/bin/python3.10)
==72582==    by 0x49CBD8F: (below main) (libc_start_call_main.h:58)
==72582== 
==72582== 167 bytes in 1 blocks are still reachable in loss record 36 of 59
==72582==    at 0x4848899: malloc (in /usr/libexec/valgrind/vgpreload_memcheck-amd64-linux.so)
==72582==    by 0x49D8607: new_composite_name (setlocale.c:170)
==72582==    by 0x49D8AEA: setlocale (setlocale.c:437)
==72582==    by 0x49D8AEA: setlocale (setlocale.c:217)
==72582==    by 0x331E40: _Py_SetLocaleFromEnv (in /usr/bin/python3.10)
==72582==    by 0x331A0E: _Py_PreInitializeFromPyArgv (in /usr/bin/python3.10)
==72582==    by 0x330EAE: ??? (in /usr/bin/python3.10)
==72582==    by 0x330E24: ??? (in /usr/bin/python3.10)
==72582==    by 0x330DFC: Py_BytesMain (in /usr/bin/python3.10)
==72582==    by 0x49CBD8F: (below main) (libc_start_call_main.h:58)
==72582== 
==72582== 176 bytes in 1 blocks are still reachable in loss record 37 of 59
==72582==    at 0x4848899: malloc (in /usr/libexec/valgrind/vgpreload_memcheck-amd64-linux.so)
==72582==    by 0x332CBA: _PyMem_RawWcsdup (in /usr/bin/python3.10)
==72582==    by 0x33543F: ??? (in /usr/bin/python3.10)
==72582==    by 0x3336ED: ??? (in /usr/bin/python3.10)
==72582==    by 0x333586: Py_InitializeFromConfig (in /usr/bin/python3.10)
==72582==    by 0x330EEF: ??? (in /usr/bin/python3.10)
==72582==    by 0x330E24: ??? (in /usr/bin/python3.10)
==72582==    by 0x330DFC: Py_BytesMain (in /usr/bin/python3.10)
==72582==    by 0x49CBD8F: (below main) (libc_start_call_main.h:58)
==72582== 
==72582== 176 bytes in 1 blocks are still reachable in loss record 38 of 59
==72582==    at 0x4848899: malloc (in /usr/libexec/valgrind/vgpreload_memcheck-amd64-linux.so)
==72582==    by 0x332CBA: _PyMem_RawWcsdup (in /usr/bin/python3.10)
==72582==    by 0x33432E: _PyWideStringList_Copy (in /usr/bin/python3.10)
==72582==    by 0x3349A2: ??? (in /usr/bin/python3.10)
==72582==    by 0x3336ED: ??? (in /usr/bin/python3.10)
==72582==    by 0x333586: Py_InitializeFromConfig (in /usr/bin/python3.10)
==72582==    by 0x330EEF: ??? (in /usr/bin/python3.10)
==72582==    by 0x330E24: ??? (in /usr/bin/python3.10)
==72582==    by 0x330DFC: Py_BytesMain (in /usr/bin/python3.10)
==72582==    by 0x49CBD8F: (below main) (libc_start_call_main.h:58)
==72582== 
==72582== 176 bytes in 1 blocks are still reachable in loss record 39 of 59
==72582==    at 0x4848899: malloc (in /usr/libexec/valgrind/vgpreload_memcheck-amd64-linux.so)
==72582==    by 0x332CBA: _PyMem_RawWcsdup (in /usr/bin/python3.10)
==72582==    by 0x33432E: _PyWideStringList_Copy (in /usr/bin/python3.10)
==72582==    by 0x333A5B: ??? (in /usr/bin/python3.10)
==72582==    by 0x3337F3: ??? (in /usr/bin/python3.10)
==72582==    by 0x333586: Py_InitializeFromConfig (in /usr/bin/python3.10)
==72582==    by 0x330EEF: ??? (in /usr/bin/python3.10)
==72582==    by 0x330E24: ??? (in /usr/bin/python3.10)
==72582==    by 0x330DFC: Py_BytesMain (in /usr/bin/python3.10)
==72582==    by 0x49CBD8F: (below main) (libc_start_call_main.h:58)
==72582== 
==72582== 176 bytes in 1 blocks are still reachable in loss record 40 of 59
==72582==    at 0x4848899: malloc (in /usr/libexec/valgrind/vgpreload_memcheck-amd64-linux.so)
==72582==    by 0x332CBA: _PyMem_RawWcsdup (in /usr/bin/python3.10)
==72582==    by 0x334158: PyConfig_SetString (in /usr/bin/python3.10)
==72582==    by 0x333CD7: ??? (in /usr/bin/python3.10)
==72582==    by 0x3337F3: ??? (in /usr/bin/python3.10)
==72582==    by 0x333586: Py_InitializeFromConfig (in /usr/bin/python3.10)
==72582==    by 0x330EEF: ??? (in /usr/bin/python3.10)
==72582==    by 0x330E24: ??? (in /usr/bin/python3.10)
==72582==    by 0x330DFC: Py_BytesMain (in /usr/bin/python3.10)
==72582==    by 0x49CBD8F: (below main) (libc_start_call_main.h:58)
==72582== 
==72582== 244 bytes in 2 blocks are still reachable in loss record 41 of 59
==72582==    at 0x4848899: malloc (in /usr/libexec/valgrind/vgpreload_memcheck-amd64-linux.so)
==72582==    by 0x332DB1: ??? (in /usr/bin/python3.10)
==72582==    by 0x331F64: Py_DecodeLocale (in /usr/bin/python3.10)
==72582==    by 0x331EE8: _PyArgv_AsWstrList (in /usr/bin/python3.10)
==72582==    by 0x3334C5: ??? (in /usr/bin/python3.10)
==72582==    by 0x33347E: PyConfig_SetBytesArgv (in /usr/bin/python3.10)
==72582==    by 0x330EDD: ??? (in /usr/bin/python3.10)
==72582==    by 0x330E24: ??? (in /usr/bin/python3.10)
==72582==    by 0x330DFC: Py_BytesMain (in /usr/bin/python3.10)
==72582==    by 0x49CBD8F: (below main) (libc_start_call_main.h:58)
==72582== 
==72582== 244 bytes in 2 blocks are still reachable in loss record 42 of 59
==72582==    at 0x4848899: malloc (in /usr/libexec/valgrind/vgpreload_memcheck-amd64-linux.so)
==72582==    by 0x332CBA: _PyMem_RawWcsdup (in /usr/bin/python3.10)
==72582==    by 0x33432E: _PyWideStringList_Copy (in /usr/bin/python3.10)
==72582==    by 0x3345B0: ??? (in /usr/bin/python3.10)
==72582==    by 0x3336ED: ??? (in /usr/bin/python3.10)
==72582==    by 0x333586: Py_InitializeFromConfig (in /usr/bin/python3.10)
==72582==    by 0x330EEF: ??? (in /usr/bin/python3.10)
==72582==    by 0x330E24: ??? (in /usr/bin/python3.10)
==72582==    by 0x330DFC: Py_BytesMain (in /usr/bin/python3.10)
==72582==    by 0x49CBD8F: (below main) (libc_start_call_main.h:58)
==72582== 
==72582== 244 bytes in 2 blocks are still reachable in loss record 43 of 59
==72582==    at 0x4848899: malloc (in /usr/libexec/valgrind/vgpreload_memcheck-amd64-linux.so)
==72582==    by 0x332CBA: _PyMem_RawWcsdup (in /usr/bin/python3.10)
==72582==    by 0x33432E: _PyWideStringList_Copy (in /usr/bin/python3.10)
==72582==    by 0x337E90: ??? (in /usr/bin/python3.10)
==72582==    by 0x333737: ??? (in /usr/bin/python3.10)
==72582==    by 0x333586: Py_InitializeFromConfig (in /usr/bin/python3.10)
==72582==    by 0x330EEF: ??? (in /usr/bin/python3.10)
==72582==    by 0x330E24: ??? (in /usr/bin/python3.10)
==72582==    by 0x330DFC: Py_BytesMain (in /usr/bin/python3.10)
==72582==    by 0x49CBD8F: (below main) (libc_start_call_main.h:58)
==72582== 
==72582== 244 bytes in 2 blocks are still reachable in loss record 44 of 59
==72582==    at 0x4848899: malloc (in /usr/libexec/valgrind/vgpreload_memcheck-amd64-linux.so)
==72582==    by 0x332CBA: _PyMem_RawWcsdup (in /usr/bin/python3.10)
==72582==    by 0x33432E: _PyWideStringList_Copy (in /usr/bin/python3.10)
==72582==    by 0x333D2B: ??? (in /usr/bin/python3.10)
==72582==    by 0x3337F3: ??? (in /usr/bin/python3.10)
==72582==    by 0x333586: Py_InitializeFromConfig (in /usr/bin/python3.10)
==72582==    by 0x330EEF: ??? (in /usr/bin/python3.10)
==72582==    by 0x330E24: ??? (in /usr/bin/python3.10)
==72582==    by 0x330DFC: Py_BytesMain (in /usr/bin/python3.10)
==72582==    by 0x49CBD8F: (below main) (libc_start_call_main.h:58)
==72582== 
==72582== 280 bytes in 1 blocks are still reachable in loss record 45 of 59
==72582==    at 0x4848899: malloc (in /usr/libexec/valgrind/vgpreload_memcheck-amd64-linux.so)
==72582==    by 0x33848D: ??? (in /usr/bin/python3.10)
==72582==    by 0x333815: ??? (in /usr/bin/python3.10)
==72582==    by 0x333586: Py_InitializeFromConfig (in /usr/bin/python3.10)
==72582==    by 0x330EEF: ??? (in /usr/bin/python3.10)
==72582==    by 0x330E24: ??? (in /usr/bin/python3.10)
==72582==    by 0x330DFC: Py_BytesMain (in /usr/bin/python3.10)
==72582==    by 0x49CBD8F: (below main) (libc_start_call_main.h:58)
==72582== 
==72582== 576 bytes in 1 blocks are still reachable in loss record 46 of 59
==72582==    at 0x4848899: malloc (in /usr/libexec/valgrind/vgpreload_memcheck-amd64-linux.so)
==72582==    by 0x2239C2: PyObject_Malloc (in /usr/bin/python3.10)
==72582==    by 0x2284A5: ??? (in /usr/bin/python3.10)
==72582==    by 0x226831: PyDict_SetDefault (in /usr/bin/python3.10)
==72582==    by 0x22A37A: PyType_Ready (in /usr/bin/python3.10)
==72582==    by 0x3397F4: ??? (in /usr/bin/python3.10)
==72582==    by 0x221ED2: ??? (in /usr/bin/python3.10)
==72582==    by 0x333867: ??? (in /usr/bin/python3.10)
==72582==    by 0x333586: Py_InitializeFromConfig (in /usr/bin/python3.10)
==72582==    by 0x330EEF: ??? (in /usr/bin/python3.10)
==72582==    by 0x330E24: ??? (in /usr/bin/python3.10)
==72582==    by 0x330DFC: Py_BytesMain (in /usr/bin/python3.10)
==72582== 
==72582== 654 bytes in 1 blocks are still reachable in loss record 47 of 59
==72582==    at 0x4848899: malloc (in /usr/libexec/valgrind/vgpreload_memcheck-amd64-linux.so)
==72582==    by 0x225288: ??? (in /usr/bin/python3.10)
==72582==    by 0x22B031: PyType_Ready (in /usr/bin/python3.10)
==72582==    by 0x22C02B: PyType_Ready (in /usr/bin/python3.10)
==72582==    by 0x339808: ??? (in /usr/bin/python3.10)
==72582==    by 0x221ED2: ??? (in /usr/bin/python3.10)
==72582==    by 0x333867: ??? (in /usr/bin/python3.10)
==72582==    by 0x333586: Py_InitializeFromConfig (in /usr/bin/python3.10)
==72582==    by 0x330EEF: ??? (in /usr/bin/python3.10)
==72582==    by 0x330E24: ??? (in /usr/bin/python3.10)
==72582==    by 0x330DFC: Py_BytesMain (in /usr/bin/python3.10)
==72582==    by 0x49CBD8F: (below main) (libc_start_call_main.h:58)
==72582== 
==72582== 768 bytes in 1 blocks are still reachable in loss record 48 of 59
==72582==    at 0x48487A9: malloc (in /usr/libexec/valgrind/vgpreload_memcheck-amd64-linux.so)
==72582==    by 0x223E41: ??? (in /usr/bin/python3.10)
==72582==    by 0x221C86: ??? (in /usr/bin/python3.10)
==72582==    by 0x333867: ??? (in /usr/bin/python3.10)
==72582==    by 0x333586: Py_InitializeFromConfig (in /usr/bin/python3.10)
==72582==    by 0x330EEF: ??? (in /usr/bin/python3.10)
==72582==    by 0x330E24: ??? (in /usr/bin/python3.10)
==72582==    by 0x330DFC: Py_BytesMain (in /usr/bin/python3.10)
==72582==    by 0x49CBD8F: (below main) (libc_start_call_main.h:58)
==72582== 
==72582== 776 bytes in 1 blocks are still reachable in loss record 49 of 59
==72582==    at 0x4848899: malloc (in /usr/libexec/valgrind/vgpreload_memcheck-amd64-linux.so)
==72582==    by 0x49D996E: _nl_intern_locale_data (loadlocale.c:97)
==72582==    by 0x49D9C28: _nl_load_locale (loadlocale.c:266)
==72582==    by 0x49D97D0: _nl_find_locale (findlocale.c:237)
==72582==    by 0x49D8A90: setlocale (setlocale.c:414)
==72582==    by 0x49D8A90: setlocale (setlocale.c:217)
==72582==    by 0x332F50: _Py_CoerceLegacyLocale (in /usr/bin/python3.10)
==72582==    by 0x331A8E: _Py_PreInitializeFromPyArgv (in /usr/bin/python3.10)
==72582==    by 0x330EAE: ??? (in /usr/bin/python3.10)
==72582==    by 0x330E24: ??? (in /usr/bin/python3.10)
==72582==    by 0x330DFC: Py_BytesMain (in /usr/bin/python3.10)
==72582==    by 0x49CBD8F: (below main) (libc_start_call_main.h:58)
==72582== 
==72582== 1,112 bytes in 1 blocks are still reachable in loss record 50 of 59
==72582==    at 0x4848899: malloc (in /usr/libexec/valgrind/vgpreload_memcheck-amd64-linux.so)
==72582==    by 0x2239C2: PyObject_Malloc (in /usr/bin/python3.10)
==72582==    by 0x2284A5: ??? (in /usr/bin/python3.10)
==72582==    by 0x226831: PyDict_SetDefault (in /usr/bin/python3.10)
==72582==    by 0x22AD76: PyType_Ready (in /usr/bin/python3.10)
==72582==    by 0x3397CC: ??? (in /usr/bin/python3.10)
==72582==    by 0x221ED2: ??? (in /usr/bin/python3.10)
==72582==    by 0x333867: ??? (in /usr/bin/python3.10)
==72582==    by 0x333586: Py_InitializeFromConfig (in /usr/bin/python3.10)
==72582==    by 0x330EEF: ??? (in /usr/bin/python3.10)
==72582==    by 0x330E24: ??? (in /usr/bin/python3.10)
==72582==    by 0x330DFC: Py_BytesMain (in /usr/bin/python3.10)
==72582== 
==72582== 1,112 bytes in 1 blocks are still reachable in loss record 51 of 59
==72582==    at 0x4848899: malloc (in /usr/libexec/valgrind/vgpreload_memcheck-amd64-linux.so)
==72582==    by 0x2239C2: PyObject_Malloc (in /usr/bin/python3.10)
==72582==    by 0x2284A5: ??? (in /usr/bin/python3.10)
==72582==    by 0x226831: PyDict_SetDefault (in /usr/bin/python3.10)
==72582==    by 0x22A37A: PyType_Ready (in /usr/bin/python3.10)
==72582==    by 0x3397E0: ??? (in /usr/bin/python3.10)
==72582==    by 0x221ED2: ??? (in /usr/bin/python3.10)
==72582==    by 0x333867: ??? (in /usr/bin/python3.10)
==72582==    by 0x333586: Py_InitializeFromConfig (in /usr/bin/python3.10)
==72582==    by 0x330EEF: ??? (in /usr/bin/python3.10)
==72582==    by 0x330E24: ??? (in /usr/bin/python3.10)
==72582==    by 0x330DFC: Py_BytesMain (in /usr/bin/python3.10)
==72582== 
==72582== 1,600 bytes in 1 blocks are still reachable in loss record 52 of 59
==72582==    at 0x48487A9: malloc (in /usr/libexec/valgrind/vgpreload_memcheck-amd64-linux.so)
==72582==    by 0x49DFA3E: extend_alias_table (localealias.c:401)
==72582==    by 0x49DFA3E: read_alias_file (localealias.c:313)
==72582==    by 0x49DFBB2: _nl_expand_alias (localealias.c:198)
==72582==    by 0x49D9477: _nl_find_locale (findlocale.c:158)
==72582==    by 0x49D8A90: setlocale (setlocale.c:414)
==72582==    by 0x49D8A90: setlocale (setlocale.c:217)
==72582==    by 0x332F50: _Py_CoerceLegacyLocale (in /usr/bin/python3.10)
==72582==    by 0x331A8E: _Py_PreInitializeFromPyArgv (in /usr/bin/python3.10)
==72582==    by 0x330EAE: ??? (in /usr/bin/python3.10)
==72582==    by 0x330E24: ??? (in /usr/bin/python3.10)
==72582==    by 0x330DFC: Py_BytesMain (in /usr/bin/python3.10)
==72582==    by 0x49CBD8F: (below main) (libc_start_call_main.h:58)
==72582== 
==72582== 2,048 bytes in 1 blocks are still reachable in loss record 53 of 59
==72582==    at 0x484DCD3: realloc (in /usr/libexec/valgrind/vgpreload_memcheck-amd64-linux.so)
==72582==    by 0x49DF93D: read_alias_file (localealias.c:333)
==72582==    by 0x49DFBB2: _nl_expand_alias (localealias.c:198)
==72582==    by 0x49D9477: _nl_find_locale (findlocale.c:158)
==72582==    by 0x49D8A90: setlocale (setlocale.c:414)
==72582==    by 0x49D8A90: setlocale (setlocale.c:217)
==72582==    by 0x332F50: _Py_CoerceLegacyLocale (in /usr/bin/python3.10)
==72582==    by 0x331A8E: _Py_PreInitializeFromPyArgv (in /usr/bin/python3.10)
==72582==    by 0x330EAE: ??? (in /usr/bin/python3.10)
==72582==    by 0x330E24: ??? (in /usr/bin/python3.10)
==72582==    by 0x330DFC: Py_BytesMain (in /usr/bin/python3.10)
==72582==    by 0x49CBD8F: (below main) (libc_start_call_main.h:58)
==72582== 
==72582== 2,208 bytes in 1 blocks are still reachable in loss record 54 of 59
==72582==    at 0x4848899: malloc (in /usr/libexec/valgrind/vgpreload_memcheck-amd64-linux.so)
==72582==    by 0x2239C2: PyObject_Malloc (in /usr/bin/python3.10)
==72582==    by 0x2284A5: ??? (in /usr/bin/python3.10)
==72582==    by 0x230843: ??? (in /usr/bin/python3.10)
==72582==    by 0x229616: PyType_Ready (in /usr/bin/python3.10)
==72582==    by 0x22C02B: PyType_Ready (in /usr/bin/python3.10)
==72582==    by 0x339808: ??? (in /usr/bin/python3.10)
==72582==    by 0x221ED2: ??? (in /usr/bin/python3.10)
==72582==    by 0x333867: ??? (in /usr/bin/python3.10)
==72582==    by 0x333586: Py_InitializeFromConfig (in /usr/bin/python3.10)
==72582==    by 0x330EEF: ??? (in /usr/bin/python3.10)
==72582==    by 0x330E24: ??? (in /usr/bin/python3.10)
==72582== 
==72582== 2,208 bytes in 1 blocks are still reachable in loss record 55 of 59
==72582==    at 0x4848899: malloc (in /usr/libexec/valgrind/vgpreload_memcheck-amd64-linux.so)
==72582==    by 0x2239C2: PyObject_Malloc (in /usr/bin/python3.10)
==72582==    by 0x2284A5: ??? (in /usr/bin/python3.10)
==72582==    by 0x226831: PyDict_SetDefault (in /usr/bin/python3.10)
==72582==    by 0x22B1A3: PyType_Ready (in /usr/bin/python3.10)
==72582==    by 0x339830: ??? (in /usr/bin/python3.10)
==72582==    by 0x221ED2: ??? (in /usr/bin/python3.10)
==72582==    by 0x333867: ??? (in /usr/bin/python3.10)
==72582==    by 0x333586: Py_InitializeFromConfig (in /usr/bin/python3.10)
==72582==    by 0x330EEF: ??? (in /usr/bin/python3.10)
==72582==    by 0x330E24: ??? (in /usr/bin/python3.10)
==72582==    by 0x330DFC: Py_BytesMain (in /usr/bin/python3.10)
==72582== 
==72582== 4,632 bytes in 1 blocks are still reachable in loss record 56 of 59
==72582==    at 0x4848899: malloc (in /usr/libexec/valgrind/vgpreload_memcheck-amd64-linux.so)
==72582==    by 0x2239C2: PyObject_Malloc (in /usr/bin/python3.10)
==72582==    by 0x2284A5: ??? (in /usr/bin/python3.10)
==72582==    by 0x226831: PyDict_SetDefault (in /usr/bin/python3.10)
==72582==    by 0x2260D1: PyUnicode_InternInPlace (in /usr/bin/python3.10)
==72582==    by 0x33A070: ??? (in /usr/bin/python3.10)
==72582==    by 0x33A0B9: PyDescr_NewClassMethod (in /usr/bin/python3.10)
==72582==    by 0x22B770: PyType_Ready (in /usr/bin/python3.10)
==72582==    by 0x3397CC: ??? (in /usr/bin/python3.10)
==72582==    by 0x221ED2: ??? (in /usr/bin/python3.10)
==72582==    by 0x333867: ??? (in /usr/bin/python3.10)
==72582==    by 0x333586: Py_InitializeFromConfig (in /usr/bin/python3.10)
==72582== 
==72582== 113,528 bytes in 1 blocks are still reachable in loss record 57 of 59
==72582==    at 0x484DA83: calloc (in /usr/libexec/valgrind/vgpreload_memcheck-amd64-linux.so)
==72582==    by 0x3380F5: PyInterpreterState_New (in /usr/bin/python3.10)
==72582==    by 0x3337D3: ??? (in /usr/bin/python3.10)
==72582==    by 0x333586: Py_InitializeFromConfig (in /usr/bin/python3.10)
==72582==    by 0x330EEF: ??? (in /usr/bin/python3.10)
==72582==    by 0x330E24: ??? (in /usr/bin/python3.10)
==72582==    by 0x330DFC: Py_BytesMain (in /usr/bin/python3.10)
==72582==    by 0x49CBD8F: (below main) (libc_start_call_main.h:58)
==72582== 
==72582== 131,072 bytes in 1 blocks are still reachable in loss record 58 of 59
==72582==    at 0x484DA83: calloc (in /usr/libexec/valgrind/vgpreload_memcheck-amd64-linux.so)
==72582==    by 0x338A09: ??? (in /usr/bin/python3.10)
==72582==    by 0x223D28: ??? (in /usr/bin/python3.10)
==72582==    by 0x221C86: ??? (in /usr/bin/python3.10)
==72582==    by 0x333867: ??? (in /usr/bin/python3.10)
==72582==    by 0x333586: Py_InitializeFromConfig (in /usr/bin/python3.10)
==72582==    by 0x330EEF: ??? (in /usr/bin/python3.10)
==72582==    by 0x330E24: ??? (in /usr/bin/python3.10)
==72582==    by 0x330DFC: Py_BytesMain (in /usr/bin/python3.10)
==72582==    by 0x49CBD8F: (below main) (libc_start_call_main.h:58)
==72582== 
==72582== 262,144 bytes in 1 blocks are still reachable in loss record 59 of 59
==72582==    at 0x484DA83: calloc (in /usr/libexec/valgrind/vgpreload_memcheck-amd64-linux.so)
==72582==    by 0x33898F: ??? (in /usr/bin/python3.10)
==72582==    by 0x223D28: ??? (in /usr/bin/python3.10)
==72582==    by 0x221C86: ??? (in /usr/bin/python3.10)
==72582==    by 0x333867: ??? (in /usr/bin/python3.10)
==72582==    by 0x333586: Py_InitializeFromConfig (in /usr/bin/python3.10)
==72582==    by 0x330EEF: ??? (in /usr/bin/python3.10)
==72582==    by 0x330E24: ??? (in /usr/bin/python3.10)
==72582==    by 0x330DFC: Py_BytesMain (in /usr/bin/python3.10)
==72582==    by 0x49CBD8F: (below main) (libc_start_call_main.h:58)
==72582== 
==72582== LEAK SUMMARY:
==72582==    definitely lost: 0 bytes in 0 blocks
==72582==    indirectly lost: 0 bytes in 0 blocks
==72582==      possibly lost: 0 bytes in 0 blocks
==72582==    still reachable: 527,999 bytes in 65 blocks
==72582==         suppressed: 0 bytes in 0 blocks
==72582== 
==72582== For lists of detected and suppressed errors, rerun with: -s
==72582== ERROR SUMMARY: 0 errors from 0 contexts (suppressed: 0 from 0)
